<?xml version="1.0" ?><!-- ===================================================================================
   --><!-- |    This document was autogenerated by xacro from /home/maximum/nerf/catkin_ws/src/alma_rsl_urdf/urdf/alma.urdf.xacro
   | --><!-- |    EDITING THIS FILE BY HAND IS NOT RECOMMENDED                
                   | --><!-- ===================================================================================
   -->
<robot name="alma">  <!-- [kg * m^2] -->  <!-- [m] -->  <!-- [m]
   -->  <!-- Base link -->
  <link name="base">
    <visual>
      <origin rpy="0 0 0" xyz="0 0 0"/>
      <geometry>
        <mesh filename="package://anymal_d/urdf/base/base_3_6_0_mesh.dae" scale="1.0 1.0     1.0"/>
      </geometry>
    </visual>
    <collision>
      <origin rpy="0 0 0" xyz="0 0 0.016"/>
      <geometry>
        <box size="0.894 0.1615 0.256"/>
      </geometry>
    </collision>
    <collision>
      <origin rpy="0 1.5707963267948966 0" xyz="0.23529999999999995 0.08075
   0"/>
      <geometry>
        <cylinder length="0.1482" radius="0.089" />
      </geometry>
    </collision>
    <collision>
      <origin rpy="0
   1.5707963267948966 0" xyz="0.23529999999999995 -0.08075 0"/>
      <geometry>
        <cylinder length="0.1482" radius="0.089"/>
      </geometry>
    </collision>
    <collision>
      <origin rpy="0 1.5707963267948966 0" xyz="-0.23529999999999995 0.08075 0"/>
      <geometry>
        <cylinder length="0.1482" radius="0.089"/>
      </geometry>
    </collision>
    <collision>
      <origin rpy="0 1.5707963267948966 0" xyz="-0.23529999999999995 -0.08075
   0"/>
      <geometry>
        <cylinder length="0.1482" radius="0.089" />
      </geometry>
    </collision>    <!-- Shell self filtering -->
    <self_filter>
      <origin rpy="0 0 0" xyz="0 0 0"/>
      <geometry>
        <box size="1.00 0.6 0.5"/>
      </geometry>
    </self_filter>
  </link>  <!-- Fixed joint to add dummy inertia link -->
  <joint name="base_to_base_inertia" type="fixed">
    <parent link="base"/>
    <child link="base_inertia" />
    <origin rpy="0 0 0" xyz="0 0 0"/>
  </joint>  <!-- Dummy inertia
   link, because KDL cannot have inertia on the base link -->
  <link name="base_inertia">
    <inertial>
      <origin rpy="0 0 0" xyz="-0.02148 0.00173 -0.04417" />
      <mass value="8.27629"/>
      <inertia ixx="0.06185585085" ixy="0.00052357046" ixz="-0.02204886469" iyy="0.46467853407" iyz="0.00058724812" izz="0.47162119244"/>
    </inertial>
  </link>  <!-- Fixed joint to add
   top shell link -->
  <joint name="base_to_body_top" type="fixed">
    <parent link="base"/>
    <child link="body_top"/>
    <origin rpy="0 0 0" xyz="0 0 0.144"/>
  </joint>  <!-- Body top link -->  <!-- Added as a separate
   link due to limitation in point_cloud_self_filter -->
  <link name="body_top">
    <self_filter>
      <origin rpy="0 0 0" xyz="-0.2 0 0"/>
      <geometry>
        <box size="0.3 0.09 0.005"/>
      </geometry>
    </self_filter>
  </link>  <!-- [kg * m^2] -->  <!-- Fixed joint base top shell -->
  <joint name="base_top_shell" type="fixed">
    <parent link="base"/>
    <child link="top_shell"/>
    <origin rpy="0 0 0" xyz="0 0 0"/>
  </joint>
  <!-- Top shell link -->
  <link name="top_shell">
    <visual>
      <origin rpy="0 0 0" xyz="0 0 0"/>
      <geometry>
        <mesh filename="package://anymal_d/urdf/base/shell/top_shell_3_6_0_mesh.dae" scale="1.0 1.0 1.0"/>
      </geometry>
    </visual>
    <inertial>
      <origin rpy="0 0 0" xyz="-0.0226 -0.00027 0.07263"/>
      <mass value="0.32381"/>
      <inertia ixx="0.00391191516" ixy="-1.078994e-05" ixz="-0.00048832706" iyy="0.01761096758" iyz="4.45768e-06" izz="0.02086102766"/>
    </inertial>
  </link>  <!-- [kg * m^2] -->  <!-- Fixed joint base bottom shell -->
  <joint name="base_bottom_shell" type="fixed">
    <parent link="base"/>
    <child link="bottom_shell"/>
    <origin rpy="0 0 0" xyz="0 0 0"/>
  </joint>
  <!-- Sbottom shell link -->
  <link name="bottom_shell">
    <visual>
      <origin rpy="0 0 0" xyz="0 0 0"/>
      <geometry>
        <mesh filename="package://anymal_d/urdf/base/shell/bottom_shell_3_6_0_mesh.dae" scale="1.0 1.0
   1.0"/>
      </geometry>
    </visual>
    <inertial>
      <origin rpy="0 0 0" xyz="9e-05 0.0 -0.0705"/>
      <mass value="0.73783"/>
      <inertia ixx="0.00724251946" ixy="8.94306e-06" ixz="7.96806e-05" iyy="0.03457730959" iyz="4.87e-09" izz="0.04075819312"/>
    </inertial>
  </link>  <!-- [kg
   * m^2] -->  <!--  [m] -->  <!-- Fixed joint base face -->
  <joint name="base_face_front" type="fixed">
    <parent link="base"/>
    <child link="face_front"/>
    <origin rpy="0 0 -0.0" xyz="0.4087 0 0.0205"/>
  </joint>
  <!-- Face structure link, visualization is part of base -->
  <link name="face_front">
    <inertial>
      <origin rpy="0 0 0" xyz="-0.0362 0.00223
   -0.02808"/>
      <mass value="0.48634"/>
      <inertia ixx="0.00077413444" ixy="1.55433e-06" ixz="6.243539e-05" iyy="0.00076586537" iyz="4.61106e-06" izz="0.00055588292"/>
    </inertial>
  </link>  <!-- [kg * m^2] -->
  <!-- Camera joint, specifies the location of the camera (disregarding the flipped
   mounting orientation)-->
  <joint name="face_front_to_depth_camera_front_lower_camera" type="fixed">
    <parent link="face_front"/>
    <child link="depth_camera_front_lower_camera" />
    <origin rpy="0.0 1.0471975511965976 0" xyz="-0.04028 -0.025 -0.08051" />
  </joint>  <!-- Camera link -->
  <link name="depth_camera_front_lower_camera">
    <inertial>
      <origin rpy="0 0 0" xyz="-0.00362 -0.01787 -0.00011" />
      <mass value="0.06355"/>
      <inertia ixx="6.841545e-05" ixy="1.46667e-06" ixz="4.115e-08" iyy="5.2817e-06" iyz="8.039e-08" izz="6.669787e-05" />
    </inertial>
  </link>  <!--    Camera parent joint; the root attachment
   point of the camera.    This one accounts for the flipped face camera orientation.
      -->  <!-- Frame lies on the left ir camera according to any_realsense2_camera
   urdf. -->
  <joint name="depth_camera_front_lower_camera_to_camera_parent" type="fixed">
    <parent link="depth_camera_front_lower_camera"/>
    <child link="depth_camera_front_lower_camera_parent"/>
    <origin rpy="3.141592653589793
   0.0 0.0" xyz="0.0 0.0 0.0"/>
  </joint>  <!-- Camera parent link -->
  <link name="depth_camera_front_lower_camera_parent"/>
  <!-- simulation or
   bagfile_is_played -->  <!-- simulation -->  <!-- [kg * m^2] -->  <!-- Camera
   joint, specifies the location of the camera (disregarding the flipped mounting
   orientation)-->
  <joint name="face_front_to_depth_camera_front_upper_camera" type="fixed">
    <parent link="face_front"/>
    <child link="depth_camera_front_upper_camera" />
    <origin rpy="0.0 0.2617993877991494 0" xyz="-0.00993 -0.025 -0.04096" />
  </joint>  <!-- Camera link -->
  <link name="depth_camera_front_upper_camera">
    <inertial>
      <origin rpy="0 0 0" xyz="-0.00362 -0.01787 -0.00011" />
      <mass value="0.06355"/>
      <inertia ixx="6.841545e-05" ixy="1.46667e-06" ixz="4.115e-08" iyy="5.2817e-06" iyz="8.039e-08" izz="6.669787e-05" />
    </inertial>
  </link>  <!--    Camera parent joint; the root attachment
   point of the camera.    This one accounts for the flipped face camera orientation.
      -->  <!-- Frame lies on the left ir camera according to any_realsense2_camera
   urdf. -->
  <joint name="depth_camera_front_upper_camera_to_camera_parent" type="fixed">
    <parent link="depth_camera_front_upper_camera"/>
    <child link="depth_camera_front_upper_camera_parent"/>
    <origin rpy="3.141592653589793
   0.0 0.0" xyz="0.0 0.0 0.0"/>
  </joint>  <!-- Camera parent link -->
  <link name="depth_camera_front_upper_camera_parent"/>
  <!-- simulation or
   bagfile_is_played -->  <!-- simulation -->  <!-- [m] -->  <!-- Camera joint
   -->
  <joint name="face_front_to_wide_angle_camera_front_camera" type="fixed">
    <parent link="face_front"/>
    <child link="wide_angle_camera_front_camera" />
    <origin rpy="0 0 0" xyz="0.0 0.0 0.0"/>
  </joint>  <!-- Camera link
   -->
  <link name="wide_angle_camera_front_camera"></link>  <!-- Camera
   parent joint -->
  <joint name="wide_angle_camera_front_camera_to_camera_parent" type="fixed">
    <parent link="wide_angle_camera_front_camera"/>
    <child link="wide_angle_camera_front_camera_parent"/>
    <origin rpy="-1.5707963267948966
   0.0 -1.5707963267948966" xyz="-0.00421 0.0 0.0"/>
  </joint>  <!-- Camera
   parent link -->
  <link name="wide_angle_camera_front_camera_parent"/>
  <!--
   simulation -->  <!-- [kg * m^2] -->  <!--  [m] -->  <!-- Fixed joint base
   face -->
  <joint name="base_face_rear" type="fixed">
    <parent link="base"/>
    <child link="face_rear"/>
    <origin rpy="0 0 3.141592653589793" xyz="-0.4087 0 0.0205"/>
  </joint>  <!-- Face structure link, visualization
   is part of base -->
  <link name="face_rear">
    <inertial>
      <origin rpy="0 0 0" xyz="-0.0362 0.00223 -0.02808"/>
      <mass value="0.48634" />
      <inertia ixx="0.00077413444" ixy="1.55433e-06" ixz="6.243539e-05" iyy="0.00076586537" iyz="4.61106e-06" izz="0.00055588292"/>
    </inertial>
  </link>  <!-- [kg * m^2] -->  <!-- Camera joint, specifies the location of
   the camera (disregarding the flipped mounting orientation)-->
  <joint name="face_rear_to_depth_camera_rear_lower_camera" type="fixed">
    <parent link="face_rear"/>
    <child link="depth_camera_rear_lower_camera"/>
    <origin rpy="0.0 1.0471975511965976 0" xyz="-0.04028 -0.025 -0.08051"/>
  </joint>
  <!-- Camera link -->
  <link name="depth_camera_rear_lower_camera">
    <inertial>
      <origin rpy="0 0 0" xyz="-0.00362 -0.01787 -0.00011"/>
      <mass value="0.06355"/>
      <inertia ixx="6.841545e-05" ixy="1.46667e-06" ixz="4.115e-08" iyy="5.2817e-06" iyz="8.039e-08" izz="6.669787e-05"/>
    </inertial>
  </link>  <!--    Camera parent joint; the root attachment point of the camera.
      This one accounts for the flipped face camera orientation.    -->  <!--
   Frame lies on the left ir camera according to any_realsense2_camera urdf. -->
  <joint name="depth_camera_rear_lower_camera_to_camera_parent" type="fixed">
    <parent link="depth_camera_rear_lower_camera"/>
    <child link="depth_camera_rear_lower_camera_parent" />
    <origin rpy="3.141592653589793 0.0 0.0" xyz="0.0 0.0 0.0"/>
  </joint>
  <!-- Camera parent link -->
  <link name="depth_camera_rear_lower_camera_parent" />
  <!-- simulation or bagfile_is_played -->  <!-- simulation -->  <!-- [kg
   * m^2] -->  <!-- Camera joint, specifies the location of the camera (disregarding
   the flipped mounting orientation)-->
  <joint name="face_rear_to_depth_camera_rear_upper_camera" type="fixed">
    <parent link="face_rear"/>
    <child link="depth_camera_rear_upper_camera" />
    <origin rpy="0.0 0.2617993877991494 0" xyz="-0.00993 -0.025 -0.04096" />
  </joint>  <!-- Camera link -->
  <link name="depth_camera_rear_upper_camera">
    <inertial>
      <origin rpy="0 0 0" xyz="-0.00362 -0.01787 -0.00011" />
      <mass value="0.06355"/>
      <inertia ixx="6.841545e-05" ixy="1.46667e-06" ixz="4.115e-08" iyy="5.2817e-06" iyz="8.039e-08" izz="6.669787e-05" />
    </inertial>
  </link>  <!--    Camera parent joint; the root attachment
   point of the camera.    This one accounts for the flipped face camera orientation.
      -->  <!-- Frame lies on the left ir camera according to any_realsense2_camera
   urdf. -->
  <joint name="depth_camera_rear_upper_camera_to_camera_parent" type="fixed">
    <parent link="depth_camera_rear_upper_camera"/>
    <child link="depth_camera_rear_upper_camera_parent"/>
    <origin rpy="3.141592653589793 0.0
   0.0" xyz="0.0 0.0 0.0"/>
  </joint>  <!-- Camera parent link -->
  <link name="depth_camera_rear_upper_camera_parent"/>
  <!-- simulation or bagfile_is_played
   -->  <!-- simulation -->  <!-- [m] -->  <!-- Camera joint -->
  <joint name="face_rear_to_wide_angle_camera_rear_camera" type="fixed">
    <parent link="face_rear"/>
    <child link="wide_angle_camera_rear_camera"/>
    <origin rpy="0 0 0" xyz="0.0 0.0 0.0"/>
  </joint>  <!-- Camera link -->
  <link name="wide_angle_camera_rear_camera"></link>  <!-- Camera parent
   joint -->
  <joint name="wide_angle_camera_rear_camera_to_camera_parent" type="fixed">
    <parent link="wide_angle_camera_rear_camera"/>
    <child link="wide_angle_camera_rear_camera_parent"/>
    <origin rpy="-1.5707963267948966
   0.0 -1.5707963267948966" xyz="-0.00421 0.0 0.0"/>
  </joint>  <!-- Camera
   parent link -->
  <link name="wide_angle_camera_rear_camera_parent"/>
  <!--
   simulation -->  <!-- [kg * m^2] -->  <!-- Fixed joint face face shell -->
  <joint name="base_face_shell_front" type="fixed">
    <parent link="face_front" />
    <child link="face_shell_front"/>
    <origin rpy="0 0 0" xyz="0 0
   0"/>
  </joint>  <!-- Face shell link -->
  <link name="face_shell_front">
    <visual>
      <origin rpy="0 0 0" xyz="0 0 0"/>
      <geometry>
        <mesh filename="package://anymal_d/urdf/base/shell/face_shell_3_6_0_mesh.dae" scale="1.0 1.0 1.0"/>
      </geometry>
    </visual>
    <inertial>
      <origin rpy="0 0 0" xyz="0.01446 4e-05 -0.01698"/>
      <mass value="0.1369"/>
      <inertia ixx="0.00102140404" ixy="9.54e-09" ixz="4.343039e-05" iyy="0.00051576362" iyz="2.7592e-07" izz="0.00057208503"/>
    </inertial>
  </link>  <!-- [kg * m^2] -->  <!-- Fixed joint face face shell -->
  <joint name="base_face_shell_rear" type="fixed">
    <parent link="face_rear" />
    <child link="face_shell_rear"/>
    <origin rpy="0 0 0" xyz="0 0 0" />
  </joint>  <!-- Face shell link -->
  <link name="face_shell_rear">
    <visual>
      <origin rpy="0 0 0" xyz="0 0 0"/>
      <geometry>
        <mesh filename="package://anymal_d/urdf/base/shell/face_shell_3_6_0_mesh.dae" scale="1.0 1.0 1.0"/>
      </geometry>
    </visual>
    <inertial>
      <origin rpy="0 0 0" xyz="0.01446 4e-05 -0.01698"/>
      <mass value="0.1369"/>
      <inertia ixx="0.00102140404" ixy="9.54e-09" ixz="4.343039e-05" iyy="0.00051576362" iyz="2.7592e-07" izz="0.00057208503"/>
    </inertial>
  </link>  <!-- [kg * m^2] -->  <!-- Fixed joint base battery -->
  <joint name="base_battery" type="fixed">
    <parent link="base"/>
    <child link="battery"/>
    <origin rpy="0 0 0" xyz="0 0 0"/>
  </joint>  <!--
   Shell link -->
  <link name="battery">
    <visual>
      <origin rpy="0 0 0" xyz="0 0 0"/>
      <geometry>
        <mesh filename="package://anymal_d/urdf/base/battery/battery_3_6_0_mesh.dae" scale="1.0 1.0     1.0"/>
      </geometry>
    </visual>
    <inertial>
      <origin rpy="0 0 0" xyz="-0.00067 0.00023 -0.02212"/>
      <mass value="5.51206"/>
      <inertia ixx="0.00745533705" ixy="-0.00016412238" ixz="7.454512e-05" iyy="0.07199300212" iyz="-1.31605e-06" izz="0.07459357231" />
    </inertial>
  </link>  <!-- [kg * m^2] -->  <!-- Fixed joint to add
   docking  -->
  <joint name="base_to_docking_socket" type="fixed">
    <parent link="base"/>
    <child link="docking_socket"/>
    <origin rpy="0 0 0" xyz="0.26132 0.0 -0.06205"/>
  </joint>  <!-- docking socket link -->
  <link name="docking_socket">
    <visual>
      <origin rpy="0 0 0" xyz="0 0 0"/>
      <geometry>
        <mesh filename="package://anymal_d/urdf/base/docking_socket/docking_socket_3_6_0_mesh.dae" scale="1.0 1.0 1.0"/>
      </geometry>
    </visual>
    <inertial>
      <origin rpy="0 0 0" xyz="0.00606 0.0 0.01903"/>
      <mass value="0.21905" />
      <inertia ixx="0.00010664534" ixy="5.383e-08" ixz="4.91832e-06" iyy="0.00015585103" iyz="1.7942e-07" izz="0.00021982177"/>
    </inertial>
  </link>
  <!-- [kg * m^2] -->  <!-- Fixed joint base battery -->
  <joint name="base_hbc_receiver" type="fixed">
    <parent link="base"/>
    <child link="hbc_receiver" />
    <origin rpy="0 0 0" xyz="-0.04350 0.0 0.14400"/>
  </joint>  <!--
   Shell link -->
  <link name="hbc_receiver">
    <inertial>
      <origin rpy="0 0 0" xyz="-0.00144 -0.00075 -0.01143"/>
      <mass value="0.60727" />
      <inertia ixx="0.00172041475" ixy="2.466045e-05" ixz="1.95244e-06" iyy="0.00100683572" iyz="3.598867e-05" izz="0.00217149159"/>
    </inertial>
  </link>
  <link name="imu_link"/>
  <joint name="imu_joint" type="fixed">
    <parent link="base"/>
    <child link="imu_link"/>
    <origin rpy="3.141592653589793 0.0 3.141592653589793" xyz="-0.25565 0.00255 0.07672"/>
  </joint>  <!-- [kg * m^2] -->  <!-- Camera joint -->
  <joint name="base_to_depth_camera_left_camera" type="fixed">
    <parent link="base"/>
    <child link="depth_camera_left_camera" />
    <origin rpy="0.0 0.7330382858376184 1.5707963267948966" xyz="-0.02500
   0.09230 0.01230"/>
  </joint>  <!-- Camera link -->
  <link name="depth_camera_left_camera">
    <inertial>
      <origin rpy="0 0 0" xyz="-0.01352 -0.02667 -0.00198" />
      <mass value="0.11196"/>
      <inertia ixx="0.00011356938" ixy="3.5285e-06" ixz="4.9332e-07" iyy="2.382311e-05" iyz="3.3737e-07" izz="0.00012178739" />
    </inertial>
  </link>  <!--    Camera parent joint; the root attachment
   point of the camera.    This is included for frame tree consistency with the
   face realsenses, which are flipped.    -->  <!-- Frame lies on the left ir
   camera according to any_realsense2_camera urdf. -->
  <joint name="depth_camera_left_camera_to_camera_parent" type="fixed">
    <parent link="depth_camera_left_camera"/>
    <child link="depth_camera_left_camera_parent"/>
    <origin rpy="0.0 0.0 0.0" xyz="0.0 0.0
   0.0"/>
  </joint>  <!-- Camera parent link -->
  <link name="depth_camera_left_camera_parent" />
  <!-- simulation or bagfile_is_played -->  <!-- simulation -->  <!-- [kg
   * m^2] -->  <!-- Camera joint -->
  <joint name="base_to_depth_camera_right_camera" type="fixed">
    <parent link="base"/>
    <child link="depth_camera_right_camera" />
    <origin rpy="0.0 0.7330382858376184 -1.5707963267948966" xyz="-0.02500
   -0.09230 0.01230"/>
  </joint>  <!-- Camera link -->
  <link name="depth_camera_right_camera">
    <inertial>
      <origin rpy="0 0 0" xyz="-0.01352 -0.02667 -0.00198" />
      <mass value="0.11196"/>
      <inertia ixx="0.00011356938" ixy="3.5285e-06" ixz="4.9332e-07" iyy="2.382311e-05" iyz="3.3737e-07" izz="0.00012178739" />
    </inertial>
  </link>  <!--    Camera parent joint; the root attachment
   point of the camera.    This is included for frame tree consistency with the
   face realsenses, which are flipped.    -->  <!-- Frame lies on the left ir
   camera according to any_realsense2_camera urdf. -->
  <joint name="depth_camera_right_camera_to_camera_parent" type="fixed">
    <parent link="depth_camera_right_camera"/>
    <child link="depth_camera_right_camera_parent"/>
    <origin rpy="0.0 0.0 0.0" xyz="0.0 0.0 0.0"/>
  </joint>  <!-- Camera parent link -->
  <link name="depth_camera_right_camera_parent" />
  <!-- simulation or bagfile_is_played -->  <!-- simulation -->  <!-- [kg
   * m^2] -->  <!-- [m] -->  <!-- Accounts for velodyne cage on top -->  <!--
   parent to sensor parent joint -->
  <joint name="base_to_lidar_parent" type="fixed">
    <parent link="base"/>
    <child link="lidar_parent"/>
    <origin rpy="0 0 1.5707963267948966" xyz="-0.310 0.0 0.1585"/>
  </joint>  <!--
   sensor parent to sensor joint. The transformation is hard-coded.    This accounts
   for the fact that the Velodyne driver rotates the measurements 90 degrees in yaw
   -->
  <joint name="lidar_parent_to_lidar" type="fixed">
    <parent link="lidar_parent"/>
    <child link="lidar"/>
    <origin rpy="0 0 1.5707963267948966" xyz="0 0 0"/>
  </joint>  <!--Sensor parent link -->
  <link name="lidar_parent"></link>  <!-- Velodyne sensor link -->
  <link name="lidar">
    <visual>
      <origin xyz="0 0 0"/>
      <geometry>
        <mesh filename="package://anymal_d/urdf/base/sensors/lidar/velodyne_3_6_0_mesh.dae" />
      </geometry>
    </visual>
    <visual>
      <origin xyz="0 0 0" />
      <geometry>
        <mesh filename="package://anymal_d/urdf/base/sensors/lidar/velodyne_guard.dae" />
      </geometry>
    </visual>
    <collision>
      <origin rpy="0 0 0" xyz="0 0 0"/>
      <geometry>
        <cylinder length="0.1355" radius="0.07"/>
      </geometry>
    </collision>
    <inertial>
      <origin rpy="0.0 0.0 0.0" xyz="-0.00371 -0.00326 -0.00485"/>
      <mass value="0.9017" />
      <inertia ixx="0.00111563406" ixy="0.00012074344" ixz="0.00011445184" iyy="0.00114682455" iyz="0.00010431906" izz="0.00132807373"/>
    </inertial>
  </link>  <!-- simulation -->  <!-- [m] -->  <!-- [rad] -->  <!-- joint
   base HAA -->
  <joint name="base_LF_HAA_drive" type="fixed">
    <parent link="base"/>
    <child link="LF_HAA_drive"/>
    <origin rpy="0 0 0.0" xyz="0.304 0.109 0.0"/>
  </joint>  <!-- [kg * m^2] -->  <!-- [m] -->
  <!-- [A] -->  <!-- Drive link -->
  <link name="LF_HAA_drive">
    <visual>
      <origin rpy="0 0 0" xyz="0 0 0"/>
      <geometry>
        <mesh filename="package://anymal_d/urdf/leg/drives/drive_3_2_0_mesh.dae" scale="1.0 1.0     1.0" />
      </geometry>
    </visual>
    <inertial>
      <origin rpy="0 0 0" xyz="-0.05783 -0.00014 0.00036"/>
      <mass value="2.01511"/>
      <inertia ixx="0.0033251482" ixy="2.567315e-05" ixz="2.599963e-05" iyy="0.00318377804" iyz="9.462185e-05" izz="0.00355095312"/>
    </inertial>
  </link>  <!--
   Joint Drive output (or parent/output) -->
  <joint name="LF_HAA" type="revolute">
    <parent link="LF_HAA_drive"/>
    <child link="LF_HIP"/>
    <origin rpy="0 0 0" xyz="0 0 0"/>
    <axis xyz="1 0 0"/>
    <limit command_effort="80.0" current="32.0" effort="80.0" gear_velocity="8.5" lower="-0.7853985" upper="0.6108655" velocity="8.5"/>
    <dynamics damping="0.0" friction="0.0"/>
  </joint>  <!-- Joint child link (dummy link, dummy inertia required
   for Gazebo)-->
  <link name="LF_HIP">
    <inertial>
      <origin rpy="0 0 0" xyz="0 0 0"/>
      <mass value="0.001"/>
      <inertia ixx="0.000001" ixy="0.0" ixz="0.0" iyy="0.000001" iyz="0.0" izz="0.000001"/>
    </inertial>
  </link>  <!-- [kg * m^2] -->  <!-- [m] -->  <!-- joint HAA hip -->
  <joint name="LF_HIP_LF_hip_fixed" type="fixed">
    <parent link="LF_HIP"/>
    <child link="LF_hip_fixed"/>
    <origin rpy="0 0 0.0" xyz="0 0 0"/>
  </joint>  <!-- Hip link -->
  <link name="LF_hip_fixed">
    <visual>
      <origin rpy="0.0 0 0.0" xyz="0 0 0"/>
      <geometry>
        <mesh filename="package://anymal_d/urdf/leg/hip/hip_3_6_0_mesh.dae" scale="1.0 1.0
       1.0"/>
      </geometry>
    </visual>    <!--      Disabled collision
   to avoid colliding with base collision model-->    <!--      <collision>-->
    <!--        <origin xyz="${front*collision_box_l*0.5} ${-left*collision_box_d*0.5}
   0" rpy="${0.5*pi} 0 0"/>-->    <!--        <geometry>-->    <!--      
      <box size="${fabs(collision_box_l)} ${fabs(collision_box_w)} ${fabs(collision_box_d)}" />-->    <!--        </geometry>-->    <!--      </collision>-->
    <inertial>
      <origin rpy="0 0 0" xyz="0.03505 -0.00125 0.0"/>
      <mass value="0.36386"/>
      <inertia ixx="0.00023646957" ixy="3.45771e-06" ixz="1.268e-08" iyy="0.00055386457" iyz="1.811e-08" izz="0.00043888609"/>
    </inertial>
  </link>  <!-- [rad] -->  <!-- joint hip to HFE output -->
  <joint name="LF_hip_fixed_LF_HFE_output" type="fixed">
    <parent link="LF_hip_fixed" />
    <child link="LF_HFE_output"/>
    <origin rpy="0 0 -1.5707963267948966" xyz="0.069 0.006 0.0"/>
  </joint>  <!-- HFE output (dummy link, dummy inertia
   required for Gazebo) -->
  <link name="LF_HFE_output">
    <inertial>
      <origin rpy="0 0 0" xyz="0 0 0"/>
      <mass value="0.001"/>
      <inertia ixx="0.000001" ixy="0.0" ixz="0.0" iyy="0.000001" iyz="0.0" izz="0.000001"/>
    </inertial>
  </link>  <!-- [kg * m^2] -->  <!--
   [m] -->  <!-- [A] -->  <!-- Drive link -->
  <link name="LF_HFE_drive">
    <visual>
      <origin rpy="0 0 0" xyz="0 0 0"/>
      <geometry>
        <mesh filename="package://anymal_d/urdf/leg/drives/drive_3_2_0_mesh.dae" scale="1.0 1.0     1.0"/>
      </geometry>
    </visual>
    <collision>
      <origin rpy="0 1.5707963267948966 0" xyz="-0.0595 0 0"/>
      <geometry>
        <cylinder length="0.119" radius="0.05375"/>
      </geometry>
    </collision>
    <inertial>
      <origin rpy="0 0 0" xyz="-0.05783 -0.00014
   0.00036"/>
      <mass value="2.01511"/>
      <inertia ixx="0.0033251482" ixy="2.567315e-05" ixz="2.599963e-05" iyy="0.00318377804" iyz="9.462185e-05" izz="0.00355095312"/>
    </inertial>
  </link>  <!-- Joint Drive output
   (or parent/output) -->
  <joint name="LF_HFE" type="revolute">
    <parent link="LF_HFE_output"/>
    <child link="LF_THIGH"/>
    <origin rpy="0
   0 0" xyz="0 0 0"/>
    <axis xyz="-1 0 0"/>
    <limit command_effort="80.0" current="32.0" effort="80.0" gear_velocity="8.5" lower="-9.42477796076938" upper="9.42477796076938" velocity="8.5"/>
    <dynamics damping="0.0" friction="0.0"/>
  </joint>  <!-- Joint child link (dummy link, dummy inertia required
   for Gazebo)-->
  <link name="LF_THIGH">
    <inertial>
      <origin rpy="0 0 0" xyz="0 0 0"/>
      <mass value="0.001"/>
      <inertia ixx="0.000001" ixy="0.0" ixz="0.0" iyy="0.000001" iyz="0.0" izz="0.000001"/>
    </inertial>
  </link>
  <joint name="LF_THIGH_to_LF_HFE_drive" type="fixed">
    <parent link="LF_THIGH"/>
    <child link="LF_HFE_drive"/>
    <origin rpy="0 0
   0" xyz="0 0 0"/>
  </joint>  <!-- [kg * m^2] -->  <!-- [m] -->  <!--
   joint HFE thigh -->
  <joint name="LF_HFE_drive_LF_thigh_fixed" type="fixed">
    <parent link="LF_HFE_drive"/>
    <child link="LF_thigh_fixed"/>
    <origin rpy="0 0 1.5707963267948966" xyz="0 0 0"/>
  </joint>  <!-- Thigh
   link -->
  <link name="LF_thigh_fixed">
    <visual>
      <origin rpy="0 0 0.0" xyz="0 0 0"/>
      <geometry>
        <mesh filename="package://anymal_d/urdf/leg/thigh/thigh_3_6_0_mesh.dae" scale="1.0 1.0     1.0"/>
      </geometry>
    </visual>    <!-- Thigh
   collision -->
    <collision>
      <origin rpy="1.5707963267948966 0 0" xyz="0 0.10519500000000001 0"/>
      <geometry>
        <cylinder length="0.08313000000000001" radius="0.07"/>
      </geometry>
    </collision>
    <collision>
      <origin rpy="0 0 0" xyz="0 0.09513 -0.1425"/>
      <geometry>
        <box size="0.093 0.063 0.285"/>
      </geometry>
    </collision>
    <collision>
      <origin rpy="1.5707963267948966 0 0" xyz="0 0.08506500000000002 -0.285" />
      <geometry>
        <cylinder length="0.08313000000000001" radius="0.07"/>
      </geometry>
    </collision>
    <inertial>
      <origin rpy="0 0 0" xyz="-0.00041 0.09155 -0.13317"/>
      <mass value="1.10098"/>
      <inertia ixx="0.01541669135" ixy="0.00021116021" ixz="0.00031942961" iyy="0.01630081575" iyz="0.00143783119" izz="0.00258410631"/>
    </inertial>
  </link>  <!-- [rad] -->  <!-- joint thigh KFE -->
  <joint name="LF_thigh_fixed_LF_KFE_drive" type="fixed">
    <parent link="LF_thigh_fixed"/>
    <child link="LF_KFE_drive" />
    <origin rpy="0 0 1.5707963267948966" xyz="0.0 0.1805 -0.285"/>
  </joint>
  <!-- [kg * m^2] -->  <!-- [m] -->  <!-- [A] -->  <!-- Drive link -->
  <link name="LF_KFE_drive">
    <visual>
      <origin rpy="0 0 0" xyz="0 0 0"/>
      <geometry>
        <mesh filename="package://anymal_d/urdf/leg/drives/drive_3_2_0_mesh.dae" scale="1.0 1.0     1.0"/>
      </geometry>
    </visual>
    <collision>
      <origin rpy="0 1.5707963267948966 0" xyz="-0.0595 0 0"/>
      <geometry>
        <cylinder length="0.119" radius="0.05375"/>
      </geometry>
    </collision>
    <inertial>
      <origin rpy="0 0 0" xyz="-0.05783 -0.00014
   0.00036"/>
      <mass value="2.01511"/>
      <inertia ixx="0.0033251482" ixy="2.567315e-05" ixz="2.599963e-05" iyy="0.00318377804" iyz="9.462185e-05" izz="0.00355095312"/>
    </inertial>
  </link>  <!-- Joint Drive output
   (or parent/output) -->
  <joint name="LF_KFE" type="revolute">
    <parent link="LF_KFE_drive"/>
    <child link="LF_SHANK"/>
    <origin rpy="0 0
   0" xyz="0 0 0"/>
    <axis xyz="1 0 0"/>
    <limit command_effort="80.0" current="32.0" effort="80.0" gear_velocity="8.5" lower="-9.42477796076938" upper="9.42477796076938" velocity="8.5"/>
    <dynamics damping="0.0" friction="0.0"/>
  </joint>  <!-- Joint child link (dummy link, dummy inertia required
   for Gazebo)-->
  <link name="LF_SHANK">
    <inertial>
      <origin rpy="0 0 0" xyz="0 0 0"/>
      <mass value="0.001"/>
      <inertia ixx="0.000001" ixy="0.0" ixz="0.0" iyy="0.000001" iyz="0.0" izz="0.000001"/>
    </inertial>
  </link>  <!-- [m] -->  <!-- joint KFE shank -->
  <joint name="LF_shank_LF_shank_fixed" type="fixed">
    <parent link="LF_SHANK"/>
    <child link="LF_shank_fixed" />
    <origin rpy="0 0 -1.5707963267948966" xyz="0 0 0"/>
  </joint>  <!--
   Shank link -->
  <link name="LF_shank_fixed">
    <visual>
      <origin rpy="0 0 0.0" xyz="0 0 0"/>
      <geometry>
        <mesh filename="package://anymal_d/urdf/leg/shank/shank_3_6_0_mesh.dae" scale="1.0 1.0     1.0"/>
      </geometry>
    </visual>    <!-- Shank
   collision -->
    <collision>
      <origin rpy="1.5707963267948966 0 0" xyz="0 0 0"/>
      <geometry>
        <cylinder length="0.05732" radius="0.071" />
      </geometry>
    </collision>
    <collision>
      <origin rpy="1.5707963267948966
   0 0" xyz="0.066415 0 0"/>
      <geometry>
        <box size="0.13283 0.08302
   0.05732"/>
      </geometry>
    </collision>
    <inertial>
      <origin rpy="0 0 0" xyz="0.02186 0.00895 0.00042"/>
      <mass value="0.49854" />
      <inertia ixx="0.00054939614" ixy="2.147115e-05" ixz="1.687902e-05" iyy="0.00166971314" iyz="1.71584e-06" izz="0.00127258622"/>
    </inertial>
  </link>  <!-- [kg * m^2] -->  <!-- Leg configurations: xx (knees bent inwards),
   xo (knees bent backwards) -->  <!-- joint shank foot -->
  <joint name="LF_shank_fixed_LF_FOOT" type="fixed">
    <parent link="LF_shank_fixed"/>
    <child link="LF_FOOT" />
    <origin rpy="0 0 0" xyz="0.1 0.02225 -0.39246"/>
  </joint>  <!--
   Foot link -->
  <link name="LF_FOOT">
    <visual>
      <origin rpy="0
   0 0.0" xyz="0 0 0"/>
      <geometry>
        <mesh filename="package://anymal_d/urdf/leg/foot/foot_3_6_1_mesh.dae" scale="1.0 1.0     1.0"/>
      </geometry>
    </visual>    <!-- Foot tube
   collision -->
    <collision>
      <origin rpy="0 0 0" xyz="0 -0.016891153063699788
   0.22824319686592265"/>
      <geometry>
        <cylinder length="0.39572" radius="0.0175"/>
      </geometry>
    </collision>    <!-- Foot ball collision
   -->
    <collision>
      <origin xyz="0 -0.008141153063699788 0.03038319686592264" />
      <geometry>
        <sphere radius="0.031455"/>
      </geometry>
    </collision>
    <inertial>
      <origin rpy="0 0 0" xyz="0.0 -0.01559
   0.15004"/>
      <mass value="0.29644"/>
      <inertia ixx="0.00514263169" ixy="1.46e-09" ixz="6.85e-09" iyy="0.0051315957" iyz="0.00016323086" izz="0.00011890148"/>
    </inertial>
  </link>  <!-- Gazebo customization -->
  <gazebo reference="LF_FOOT">
    <kp>1000000.0</kp>
    <kd>100.0</kd>
    <mu1>0.8</mu1>
    <mu2>0.8</mu2>
  </gazebo>  <!-- [m] -->  <!-- [rad]
   -->  <!-- joint base HAA -->
  <joint name="base_RF_HAA_drive" type="fixed">
    <parent link="base"/>
    <child link="RF_HAA_drive"/>
    <origin rpy="0 0 0.0" xyz="0.304 -0.109 0.0"/>
  </joint>  <!-- [kg * m^2] -->
  <!-- [m] -->  <!-- [A] -->  <!-- Drive link -->
  <link name="RF_HAA_drive">
    <visual>
      <origin rpy="0 0 0" xyz="0 0 0"/>
      <geometry>
        <mesh filename="package://anymal_d/urdf/leg/drives/drive_3_2_0_mesh.dae" scale="1.0 1.0     1.0"/>
      </geometry>
    </visual>
    <inertial>
      <origin rpy="0 0 0" xyz="-0.05783 -0.00014 0.00036"/>
      <mass value="2.01511"/>
      <inertia ixx="0.0033251482" ixy="2.567315e-05" ixz="2.599963e-05" iyy="0.00318377804" iyz="9.462185e-05" izz="0.00355095312"/>
    </inertial>
  </link>  <!-- Joint Drive output (or parent/output) -->
  <joint name="RF_HAA" type="revolute">
    <parent link="RF_HAA_drive"/>
    <child link="RF_HIP" />
    <origin rpy="0 0 0" xyz="0 0 0"/>
    <axis xyz="1 0 0"/>
    <limit command_effort="80.0" current="32.0" effort="80.0" gear_velocity="8.5" lower="-0.6108655" upper="0.7853985" velocity="8.5"/>
    <dynamics damping="0.0" friction="0.0"/>
  </joint>  <!-- Joint child link (dummy link, dummy
   inertia required for Gazebo)-->
  <link name="RF_HIP">
    <inertial>
      <origin rpy="0 0 0" xyz="0 0 0"/>
      <mass value="0.001"/>
      <inertia ixx="0.000001" ixy="0.0" ixz="0.0" iyy="0.000001" iyz="0.0" izz="0.000001"/>
    </inertial>
  </link>  <!-- [kg * m^2] -->  <!--
   [m] -->  <!-- joint HAA hip -->
  <joint name="RF_HIP_RF_hip_fixed" type="fixed">
    <parent link="RF_HIP"/>
    <child link="RF_hip_fixed"/>
    <origin rpy="0 0 0.0" xyz="0 0 0"/>
  </joint>  <!-- Hip link -->
  <link name="RF_hip_fixed">
    <visual>
      <origin rpy="-3.141592653589793 0
   0.0" xyz="0 0 0"/>
      <geometry>
        <mesh filename="package://anymal_d/urdf/leg/hip/hip_3_6_0_mesh.dae" scale="1.0 1.0     1.0"/>
      </geometry>
    </visual>    <!--      Disabled
   collision to avoid colliding with base collision model-->    <!--      <collision>-->
    <!--        <origin xyz="${front*collision_box_l*0.5} ${-left*collision_box_d*0.5}
   0" rpy="${0.5*pi} 0 0"/>-->    <!--        <geometry>-->    <!--      
      <box size="${fabs(collision_box_l)} ${fabs(collision_box_w)} ${fabs(collision_box_d)}" />-->    <!--        </geometry>-->    <!--      </collision>-->
    <inertial>
      <origin rpy="0 0 0" xyz="0.03505 0.00125 0.0"/>
      <mass value="0.36386"/>
      <inertia ixx="0.00023646957" ixy="-3.45771e-06" ixz="1.268e-08" iyy="0.00055386457" iyz="-1.811e-08" izz="0.00043888609"/>
    </inertial>
  </link>  <!-- [rad] -->  <!-- joint hip to HFE output -->
  <joint name="RF_hip_fixed_RF_HFE_output" type="fixed">
    <parent link="RF_hip_fixed" />
    <child link="RF_HFE_output"/>
    <origin rpy="0 0 1.5707963267948966" xyz="0.069 -0.006 0.0"/>
  </joint>  <!-- HFE output (dummy link, dummy inertia
   required for Gazebo) -->
  <link name="RF_HFE_output">
    <inertial>
      <origin rpy="0 0 0" xyz="0 0 0"/>
      <mass value="0.001"/>
      <inertia ixx="0.000001" ixy="0.0" ixz="0.0" iyy="0.000001" iyz="0.0" izz="0.000001"/>
    </inertial>
  </link>  <!-- [kg * m^2] -->  <!--
   [m] -->  <!-- [A] -->  <!-- Drive link -->
  <link name="RF_HFE_drive">
    <visual>
      <origin rpy="0 0 0" xyz="0 0 0"/>
      <geometry>
        <mesh filename="package://anymal_d/urdf/leg/drives/drive_3_2_0_mesh.dae" scale="1.0 1.0     1.0"/>
      </geometry>
    </visual>
    <collision>
      <origin rpy="0 1.5707963267948966 0" xyz="-0.0595 0 0"/>
      <geometry>
        <cylinder length="0.119" radius="0.05375"/>
      </geometry>
    </collision>
    <inertial>
      <origin rpy="0 0 0" xyz="-0.05783 -0.00014
   0.00036"/>
      <mass value="2.01511"/>
      <inertia ixx="0.0033251482" ixy="2.567315e-05" ixz="2.599963e-05" iyy="0.00318377804" iyz="9.462185e-05" izz="0.00355095312"/>
    </inertial>
  </link>  <!-- Joint Drive output
   (or parent/output) -->
  <joint name="RF_HFE" type="revolute">
    <parent link="RF_HFE_output"/>
    <child link="RF_THIGH"/>
    <origin rpy="0
   0 0" xyz="0 0 0"/>
    <axis xyz="1 0 0"/>
    <limit command_effort="80.0" current="32.0" effort="80.0" gear_velocity="8.5" lower="-9.42477796076938" upper="9.42477796076938" velocity="8.5"/>
    <dynamics damping="0.0" friction="0.0"/>
  </joint>  <!-- Joint child link (dummy link, dummy inertia required
   for Gazebo)-->
  <link name="RF_THIGH">
    <inertial>
      <origin rpy="0 0 0" xyz="0 0 0"/>
      <mass value="0.001"/>
      <inertia ixx="0.000001" ixy="0.0" ixz="0.0" iyy="0.000001" iyz="0.0" izz="0.000001"/>
    </inertial>
  </link>
  <joint name="RF_THIGH_to_RF_HFE_drive" type="fixed">
    <parent link="RF_THIGH"/>
    <child link="RF_HFE_drive"/>
    <origin rpy="0 0
   0" xyz="0 0 0"/>
  </joint>  <!-- [kg * m^2] -->  <!-- [m] -->  <!--
   joint HFE thigh -->
  <joint name="RF_HFE_drive_RF_thigh_fixed" type="fixed">
    <parent link="RF_HFE_drive"/>
    <child link="RF_thigh_fixed"/>
    <origin rpy="0 0 -1.5707963267948966" xyz="0 0 0"/>
  </joint>  <!--
   Thigh link -->
  <link name="RF_thigh_fixed">
    <visual>
      <origin rpy="0 0 -3.141592653589793" xyz="0 0 0"/>
      <geometry>
        <mesh filename="package://anymal_d/urdf/leg/thigh/thigh_3_6_0_mesh.dae" scale="1.0
   1.0     1.0"/>
      </geometry>
    </visual>    <!-- Thigh collision -->
    <collision>
      <origin rpy="1.5707963267948966 0 0" xyz="0 -0.10519500000000001
   0"/>
      <geometry>
        <cylinder length="0.08313000000000001" radius="0.07"/>
      </geometry>
    </collision>
    <collision>
      <origin rpy="0 0 0" xyz="0 -0.09513 -0.1425"/>
      <geometry>
        <box size="0.093
   0.063 0.285"/>
      </geometry>
    </collision>
    <collision>
      <origin rpy="1.5707963267948966 0 0" xyz="0 -0.08506500000000002 -0.285"/>
      <geometry>
        <cylinder length="0.08313000000000001" radius="0.07"/>
      </geometry>
    </collision>
    <inertial>
      <origin rpy="0 0 0" xyz="-0.00041 -0.09155 -0.13317"/>
      <mass value="1.10098"/>
      <inertia ixx="0.01541669135" ixy="-0.00021116021" ixz="0.00031942961" iyy="0.01630081575" iyz="-0.00143783119" izz="0.00258410631"/>
    </inertial>
  </link>
  <!-- [rad] -->  <!-- joint thigh KFE -->
  <joint name="RF_thigh_fixed_RF_KFE_drive" type="fixed">
    <parent link="RF_thigh_fixed"/>
    <child link="RF_KFE_drive" />
    <origin rpy="0 0 -1.5707963267948966" xyz="0.0 -0.1805 -0.285"/>
  </joint>  <!-- [kg * m^2] -->  <!-- [m] -->  <!-- [A] -->  <!-- Drive
   link -->
  <link name="RF_KFE_drive">
    <visual>
      <origin rpy="0
   0 0" xyz="0 0 0"/>
      <geometry>
        <mesh filename="package://anymal_d/urdf/leg/drives/drive_3_2_0_mesh.dae" scale="1.0 1.0     1.0"/>
      </geometry>
    </visual>
    <collision>
      <origin rpy="0 1.5707963267948966 0" xyz="-0.0595 0 0"/>
      <geometry>
        <cylinder length="0.119" radius="0.05375"/>
      </geometry>
    </collision>
    <inertial>
      <origin rpy="0 0 0" xyz="-0.05783 -0.00014
   0.00036"/>
      <mass value="2.01511"/>
      <inertia ixx="0.0033251482" ixy="2.567315e-05" ixz="2.599963e-05" iyy="0.00318377804" iyz="9.462185e-05" izz="0.00355095312"/>
    </inertial>
  </link>  <!-- Joint Drive output
   (or parent/output) -->
  <joint name="RF_KFE" type="revolute">
    <parent link="RF_KFE_drive"/>
    <child link="RF_SHANK"/>
    <origin rpy="0 0
   0" xyz="0 0 0"/>
    <axis xyz="-1 0 0"/>
    <limit command_effort="80.0" current="32.0" effort="80.0" gear_velocity="8.5" lower="-9.42477796076938" upper="9.42477796076938" velocity="8.5"/>
    <dynamics damping="0.0" friction="0.0"/>
  </joint>  <!-- Joint child link (dummy link, dummy inertia required
   for Gazebo)-->
  <link name="RF_SHANK">
    <inertial>
      <origin rpy="0 0 0" xyz="0 0 0"/>
      <mass value="0.001"/>
      <inertia ixx="0.000001" ixy="0.0" ixz="0.0" iyy="0.000001" iyz="0.0" izz="0.000001"/>
    </inertial>
  </link>  <!-- [m] -->  <!-- joint KFE shank -->
  <joint name="RF_shank_RF_shank_fixed" type="fixed">
    <parent link="RF_SHANK"/>
    <child link="RF_shank_fixed" />
    <origin rpy="0 0 1.5707963267948966" xyz="0 0 0"/>
  </joint>  <!--
   Shank link -->
  <link name="RF_shank_fixed">
    <visual>
      <origin rpy="0 0 0.0" xyz="0 0 0"/>
      <geometry>
        <mesh filename="package://anymal_d/urdf/leg/shank/shank_3_6_0_mesh_mirrored.dae" scale="1.0 1.0     1.0"/>
      </geometry>
    </visual>    <!-- Shank
   collision -->
    <collision>
      <origin rpy="1.5707963267948966 0 0" xyz="0 0 0"/>
      <geometry>
        <cylinder length="0.05732" radius="0.071" />
      </geometry>
    </collision>
    <collision>
      <origin rpy="1.5707963267948966
   0 0" xyz="0.066415 0 0"/>
      <geometry>
        <box size="0.13283 0.08302
   0.05732"/>
      </geometry>
    </collision>
    <inertial>
      <origin rpy="0 0 0" xyz="0.02186 -0.00895 0.00042"/>
      <mass value="0.49854" />
      <inertia ixx="0.00054939614" ixy="-2.147115e-05" ixz="1.687902e-05" iyy="0.00166971314" iyz="-1.71584e-06" izz="0.00127258622"/>
    </inertial>
  </link>  <!-- [kg * m^2] -->  <!-- Leg configurations: xx (knees bent inwards),
   xo (knees bent backwards) -->  <!-- joint shank foot -->
  <joint name="RF_shank_fixed_RF_FOOT" type="fixed">
    <parent link="RF_shank_fixed"/>
    <child link="RF_FOOT" />
    <origin rpy="0 0 0" xyz="0.1 -0.02225 -0.39246"/>
  </joint>  <!--
   Foot link -->
  <link name="RF_FOOT">
    <visual>
      <origin rpy="0
   0 -3.141592653589793" xyz="0 0 0"/>
      <geometry>
        <mesh filename="package://anymal_d/urdf/leg/foot/foot_3_6_1_mesh.dae" scale="1.0 1.0     1.0" />
      </geometry>
    </visual>    <!-- Foot tube collision -->
    <collision>
      <origin rpy="0 0 0" xyz="0 0.016891153063699788 0.22824319686592265" />
      <geometry>
        <cylinder length="0.39572" radius="0.0175"/>
      </geometry>
    </collision>    <!-- Foot ball collision -->
    <collision>
      <origin xyz="0 0.008141153063699788 0.03038319686592264"/>
      <geometry>
        <sphere radius="0.031455"/>
      </geometry>
    </collision>
    <inertial>
      <origin rpy="0 0 0" xyz="0.0 0.01559 0.15004"/>
      <mass value="0.29644"/>
      <inertia ixx="0.00514263169" ixy="-1.46e-09" ixz="6.85e-09" iyy="0.0051315957" iyz="-0.00016323086" izz="0.00011890148" />
    </inertial>
  </link>  <!-- Gazebo customization -->
  <gazebo reference="RF_FOOT">
    <kp>1000000.0</kp>
    <kd>100.0</kd>
    <mu1>0.8</mu1>
    <mu2>0.8</mu2>
  </gazebo>  <!-- [m] -->  <!-- [rad] -->  <!-- joint base
   HAA -->
  <joint name="base_LH_HAA_drive" type="fixed">
    <parent link="base"/>
    <child link="LH_HAA_drive"/>
    <origin rpy="0 0 -3.141592653589793" xyz="-0.304 0.109 0.0"/>
  </joint>  <!-- [kg * m^2] -->  <!-- [m] -->
  <!-- [A] -->  <!-- Drive link -->
  <link name="LH_HAA_drive">
    <visual>
      <origin rpy="0 0 0" xyz="0 0 0"/>
      <geometry>
        <mesh filename="package://anymal_d/urdf/leg/drives/drive_3_2_0_mesh.dae" scale="1.0 1.0     1.0" />
      </geometry>
    </visual>
    <inertial>
      <origin rpy="0 0 0" xyz="-0.05783 -0.00014 0.00036"/>
      <mass value="2.01511"/>
      <inertia ixx="0.0033251482" ixy="2.567315e-05" ixz="2.599963e-05" iyy="0.00318377804" iyz="9.462185e-05" izz="0.00355095312"/>
    </inertial>
  </link>  <!--
   Joint Drive output (or parent/output) -->
  <joint name="LH_HAA" type="revolute">
    <parent link="LH_HAA_drive"/>
    <child link="LH_HIP"/>
    <origin rpy="0 0 0" xyz="0 0 0"/>
    <axis xyz="-1 0 0"/>
    <limit command_effort="80.0" current="32.0" effort="80.0" gear_velocity="8.5" lower="-0.7853985" upper="0.6108655" velocity="8.5"/>
    <dynamics damping="0.0" friction="0.0"/>
  </joint>  <!-- Joint child link (dummy link, dummy inertia required
   for Gazebo)-->
  <link name="LH_HIP">
    <inertial>
      <origin rpy="0 0 0" xyz="0 0 0"/>
      <mass value="0.001"/>
      <inertia ixx="0.000001" ixy="0.0" ixz="0.0" iyy="0.000001" iyz="0.0" izz="0.000001"/>
    </inertial>
  </link>  <!-- [kg * m^2] -->  <!-- [m] -->  <!-- joint HAA hip -->
  <joint name="LH_HIP_LH_hip_fixed" type="fixed">
    <parent link="LH_HIP"/>
    <child link="LH_hip_fixed"/>
    <origin rpy="0 0 -3.141592653589793" xyz="0 0 0"/>
  </joint>  <!-- Hip link -->
  <link name="LH_hip_fixed">
    <visual>
      <origin rpy="-3.141592653589793 0 -3.141592653589793" xyz="0 0 0"/>
      <geometry>
        <mesh filename="package://anymal_d/urdf/leg/hip/hip_3_6_0_mesh.dae" scale="1.0 1.0     1.0"/>
      </geometry>
    </visual>    <!--      Disabled
   collision to avoid colliding with base collision model-->    <!--      <collision>-->
    <!--        <origin xyz="${front*collision_box_l*0.5} ${-left*collision_box_d*0.5}
   0" rpy="${0.5*pi} 0 0"/>-->    <!--        <geometry>-->    <!--      
      <box size="${fabs(collision_box_l)} ${fabs(collision_box_w)} ${fabs(collision_box_d)}" />-->    <!--        </geometry>-->    <!--      </collision>-->
    <inertial>
      <origin rpy="0 0 0" xyz="-0.03505 -0.00125 0.0"/>
      <mass value="0.36386"/>
      <inertia ixx="0.00023646957" ixy="-3.45771e-06" ixz="-1.268e-08" iyy="0.00055386457" iyz="1.811e-08" izz="0.00043888609"/>
    </inertial>
  </link>  <!-- [rad] -->  <!-- joint hip to HFE output -->
  <joint name="LH_hip_fixed_LH_HFE_output" type="fixed">
    <parent link="LH_hip_fixed" />
    <child link="LH_HFE_output"/>
    <origin rpy="0 0 -1.5707963267948966" xyz="-0.069 0.006 0.0"/>
  </joint>  <!-- HFE output (dummy link, dummy inertia
   required for Gazebo) -->
  <link name="LH_HFE_output">
    <inertial>
      <origin rpy="0 0 0" xyz="0 0 0"/>
      <mass value="0.001"/>
      <inertia ixx="0.000001" ixy="0.0" ixz="0.0" iyy="0.000001" iyz="0.0" izz="0.000001"/>
    </inertial>
  </link>  <!-- [kg * m^2] -->  <!--
   [m] -->  <!-- [A] -->  <!-- Drive link -->
  <link name="LH_HFE_drive">
    <visual>
      <origin rpy="0 0 0" xyz="0 0 0"/>
      <geometry>
        <mesh filename="package://anymal_d/urdf/leg/drives/drive_3_2_0_mesh.dae" scale="1.0 1.0     1.0"/>
      </geometry>
    </visual>
    <collision>
      <origin rpy="0 1.5707963267948966 0" xyz="-0.0595 0 0"/>
      <geometry>
        <cylinder length="0.119" radius="0.05375"/>
      </geometry>
    </collision>
    <inertial>
      <origin rpy="0 0 0" xyz="-0.05783 -0.00014
   0.00036"/>
      <mass value="2.01511"/>
      <inertia ixx="0.0033251482" ixy="2.567315e-05" ixz="2.599963e-05" iyy="0.00318377804" iyz="9.462185e-05" izz="0.00355095312"/>
    </inertial>
  </link>  <!-- Joint Drive output
   (or parent/output) -->
  <joint name="LH_HFE" type="revolute">
    <parent link="LH_HFE_output"/>
    <child link="LH_THIGH"/>
    <origin rpy="0
   0 0" xyz="0 0 0"/>
    <axis xyz="-1 0 0"/>
    <limit command_effort="80.0" current="32.0" effort="80.0" gear_velocity="8.5" lower="-9.42477796076938" upper="9.42477796076938" velocity="8.5"/>
    <dynamics damping="0.0" friction="0.0"/>
  </joint>  <!-- Joint child link (dummy link, dummy inertia required
   for Gazebo)-->
  <link name="LH_THIGH">
    <inertial>
      <origin rpy="0 0 0" xyz="0 0 0"/>
      <mass value="0.001"/>
      <inertia ixx="0.000001" ixy="0.0" ixz="0.0" iyy="0.000001" iyz="0.0" izz="0.000001"/>
    </inertial>
  </link>
  <joint name="LH_THIGH_to_LH_HFE_drive" type="fixed">
    <parent link="LH_THIGH"/>
    <child link="LH_HFE_drive"/>
    <origin rpy="0 0
   0" xyz="0 0 0"/>
  </joint>  <!-- [kg * m^2] -->  <!-- [m] -->  <!--
   joint HFE thigh -->
  <joint name="LH_HFE_drive_LH_thigh_fixed" type="fixed">
    <parent link="LH_HFE_drive"/>
    <child link="LH_thigh_fixed"/>
    <origin rpy="0 0 1.5707963267948966" xyz="0 0 0"/>
  </joint>  <!-- Thigh
   link -->
  <link name="LH_thigh_fixed">
    <visual>
      <origin rpy="0 0 0.0" xyz="0 0 0"/>
      <geometry>
        <mesh filename="package://anymal_d/urdf/leg/thigh/thigh_3_6_0_mesh.dae" scale="1.0 1.0     1.0"/>
      </geometry>
    </visual>    <!-- Thigh
   collision -->
    <collision>
      <origin rpy="1.5707963267948966 0 0" xyz="0 0.10519500000000001 0"/>
      <geometry>
        <cylinder length="0.08313000000000001" radius="0.07"/>
      </geometry>
    </collision>
    <collision>
      <origin rpy="0 0 0" xyz="0 0.09513 -0.1425"/>
      <geometry>
        <box size="0.093 0.063 0.285"/>
      </geometry>
    </collision>
    <collision>
      <origin rpy="1.5707963267948966 0 0" xyz="0 0.08506500000000002 -0.285" />
      <geometry>
        <cylinder length="0.08313000000000001" radius="0.07"/>
      </geometry>
    </collision>
    <inertial>
      <origin rpy="0 0 0" xyz="0.00041 0.09155 -0.13317"/>
      <mass value="1.10098"/>
      <inertia ixx="0.01541669135" ixy="-0.00021116021" ixz="-0.00031942961" iyy="0.01630081575" iyz="0.00143783119" izz="0.00258410631"/>
    </inertial>
  </link>  <!-- [rad] -->  <!-- joint thigh KFE -->
  <joint name="LH_thigh_fixed_LH_KFE_drive" type="fixed">
    <parent link="LH_thigh_fixed"/>
    <child link="LH_KFE_drive" />
    <origin rpy="0 0 1.5707963267948966" xyz="-0.0 0.1805 -0.285"/>
  </joint>
  <!-- [kg * m^2] -->  <!-- [m] -->  <!-- [A] -->  <!-- Drive link -->
  <link name="LH_KFE_drive">
    <visual>
      <origin rpy="0 0 0" xyz="0 0 0"/>
      <geometry>
        <mesh filename="package://anymal_d/urdf/leg/drives/drive_3_2_0_mesh.dae" scale="1.0 1.0     1.0"/>
      </geometry>
    </visual>
    <collision>
      <origin rpy="0 1.5707963267948966 0" xyz="-0.0595 0 0"/>
      <geometry>
        <cylinder length="0.119" radius="0.05375"/>
      </geometry>
    </collision>
    <inertial>
      <origin rpy="0 0 0" xyz="-0.05783 -0.00014
   0.00036"/>
      <mass value="2.01511"/>
      <inertia ixx="0.0033251482" ixy="2.567315e-05" ixz="2.599963e-05" iyy="0.00318377804" iyz="9.462185e-05" izz="0.00355095312"/>
    </inertial>
  </link>  <!-- Joint Drive output
   (or parent/output) -->
  <joint name="LH_KFE" type="revolute">
    <parent link="LH_KFE_drive"/>
    <child link="LH_SHANK"/>
    <origin rpy="0 0
   0" xyz="0 0 0"/>
    <axis xyz="1 0 0"/>
    <limit command_effort="80.0" current="32.0" effort="80.0" gear_velocity="8.5" lower="-9.42477796076938" upper="9.42477796076938" velocity="8.5"/>
    <dynamics damping="0.0" friction="0.0"/>
  </joint>  <!-- Joint child link (dummy link, dummy inertia required
   for Gazebo)-->
  <link name="LH_SHANK">
    <inertial>
      <origin rpy="0 0 0" xyz="0 0 0"/>
      <mass value="0.001"/>
      <inertia ixx="0.000001" ixy="0.0" ixz="0.0" iyy="0.000001" iyz="0.0" izz="0.000001"/>
    </inertial>
  </link>  <!-- [m] -->  <!-- joint KFE shank -->
  <joint name="LH_shank_LH_shank_fixed" type="fixed">
    <parent link="LH_SHANK"/>
    <child link="LH_shank_fixed" />
    <origin rpy="0 0 -1.5707963267948966" xyz="0 0 0"/>
  </joint>  <!--
   Shank link -->
  <link name="LH_shank_fixed">
    <visual>
      <origin rpy="0 0 -3.141592653589793" xyz="0 0 0"/>
      <geometry>
        <mesh filename="package://anymal_d/urdf/leg/shank/shank_3_6_0_mesh_mirrored.dae" scale="1.0 1.0     1.0"/>
      </geometry>
    </visual>    <!-- Shank collision
   -->
    <collision>
      <origin rpy="1.5707963267948966 0 0" xyz="0 0 0" />
      <geometry>
        <cylinder length="0.05732" radius="0.071"/>
      </geometry>
    </collision>
    <collision>
      <origin rpy="1.5707963267948966
   0 0" xyz="-0.066415 0 0"/>
      <geometry>
        <box size="0.13283 0.08302
   0.05732"/>
      </geometry>
    </collision>
    <inertial>
      <origin rpy="0 0 0" xyz="-0.02186 0.00895 0.00042"/>
      <mass value="0.49854" />
      <inertia ixx="0.00054939614" ixy="-2.147115e-05" ixz="-1.687902e-05" iyy="0.00166971314" iyz="1.71584e-06" izz="0.00127258622"/>
    </inertial>
  </link>  <!-- [kg * m^2] -->  <!-- Leg configurations: xx (knees bent inwards),
   xo (knees bent backwards) -->  <!-- joint shank foot -->
  <joint name="LH_shank_fixed_LH_FOOT" type="fixed">
    <parent link="LH_shank_fixed"/>
    <child link="LH_FOOT" />
    <origin rpy="0 0 0" xyz="-0.1 0.02225 -0.39246"/>
  </joint>  <!--
   Foot link -->
  <link name="LH_FOOT">
    <visual>
      <origin rpy="0
   0 0.0" xyz="0 0 0"/>
      <geometry>
        <mesh filename="package://anymal_d/urdf/leg/foot/foot_3_6_1_mesh.dae" scale="1.0 1.0     1.0"/>
      </geometry>
    </visual>    <!-- Foot tube
   collision -->
    <collision>
      <origin rpy="0 0 0" xyz="0 -0.016891153063699788
   0.22824319686592265"/>
      <geometry>
        <cylinder length="0.39572" radius="0.0175"/>
      </geometry>
    </collision>    <!-- Foot ball collision
   -->
    <collision>
      <origin xyz="0 -0.008141153063699788 0.03038319686592264" />
      <geometry>
        <sphere radius="0.031455"/>
      </geometry>
    </collision>
    <inertial>
      <origin rpy="0 0 0" xyz="-0.0 -0.01559
   0.15004"/>
      <mass value="0.29644"/>
      <inertia ixx="0.00514263169" ixy="-1.46e-09" ixz="-6.85e-09" iyy="0.0051315957" iyz="0.00016323086" izz="0.00011890148"/>
    </inertial>
  </link>  <!-- Gazebo customization
   -->
  <gazebo reference="LH_FOOT">
    <kp>1000000.0</kp>
    <kd>100.0</kd>
    <mu1>0.8</mu1>
    <mu2>0.8</mu2>
  </gazebo>  <!-- [m] -->  <!-- [rad]
   -->  <!-- joint base HAA -->
  <joint name="base_RH_HAA_drive" type="fixed">
    <parent link="base"/>
    <child link="RH_HAA_drive"/>
    <origin rpy="0 0 -3.141592653589793" xyz="-0.304 -0.109 0.0"/>
  </joint>  <!--
   [kg * m^2] -->  <!-- [m] -->  <!-- [A] -->  <!-- Drive link -->
  <link name="RH_HAA_drive">
    <visual>
      <origin rpy="0 0 0" xyz="0 0 0" />
      <geometry>
        <mesh filename="package://anymal_d/urdf/leg/drives/drive_3_2_0_mesh.dae" scale="1.0 1.0     1.0"/>
      </geometry>
    </visual>
    <inertial>
      <origin rpy="0 0 0" xyz="-0.05783 -0.00014 0.00036"/>
      <mass value="2.01511"/>
      <inertia ixx="0.0033251482" ixy="2.567315e-05" ixz="2.599963e-05" iyy="0.00318377804" iyz="9.462185e-05" izz="0.00355095312"/>
    </inertial>
  </link>  <!-- Joint Drive output (or parent/output) -->
  <joint name="RH_HAA" type="revolute">
    <parent link="RH_HAA_drive"/>
    <child link="RH_HIP" />
    <origin rpy="0 0 0" xyz="0 0 0"/>
    <axis xyz="-1 0 0"/>
    <limit command_effort="80.0" current="32.0" effort="80.0" gear_velocity="8.5" lower="-0.6108655" upper="0.7853985" velocity="8.5"/>
    <dynamics damping="0.0" friction="0.0"/>
  </joint>  <!-- Joint child link (dummy link, dummy
   inertia required for Gazebo)-->
  <link name="RH_HIP">
    <inertial>
      <origin rpy="0 0 0" xyz="0 0 0"/>
      <mass value="0.001"/>
      <inertia ixx="0.000001" ixy="0.0" ixz="0.0" iyy="0.000001" iyz="0.0" izz="0.000001"/>
    </inertial>
  </link>  <!-- [kg * m^2] -->  <!--
   [m] -->  <!-- joint HAA hip -->
  <joint name="RH_HIP_RH_hip_fixed" type="fixed">
    <parent link="RH_HIP"/>
    <child link="RH_hip_fixed"/>
    <origin rpy="0 0 -3.141592653589793" xyz="0 0 0"/>
  </joint>  <!-- Hip
   link -->
  <link name="RH_hip_fixed">
    <visual>
      <origin rpy="0.0
   0 -3.141592653589793" xyz="0 0 0"/>
      <geometry>
        <mesh filename="package://anymal_d/urdf/leg/hip/hip_3_6_0_mesh.dae" scale="1.0 1.0     1.0"/>
      </geometry>
    </visual>    <!--      Disabled collision to avoid colliding
   with base collision model-->    <!--      <collision>-->    <!--        <origin xyz="${front*collision_box_l*0.5} ${-left*collision_box_d*0.5} 0" rpy="${0.5*pi}
   0 0"/>-->    <!--        <geometry>-->    <!--          <box size="${fabs(collision_box_l)}
   ${fabs(collision_box_w)} ${fabs(collision_box_d)}"/>-->    <!--        </geometry>-->
    <!--      </collision>-->
    <inertial>
      <origin rpy="0 0 0" xyz="-0.03505 0.00125 0.0"/>
      <mass value="0.36386"/>
      <inertia ixx="0.00023646957" ixy="3.45771e-06" ixz="-1.268e-08" iyy="0.00055386457" iyz="-1.811e-08" izz="0.00043888609"/>
    </inertial>
  </link>  <!-- [rad] -->
  <!-- joint hip to HFE output -->
  <joint name="RH_hip_fixed_RH_HFE_output" type="fixed">
    <parent link="RH_hip_fixed"/>
    <child link="RH_HFE_output" />
    <origin rpy="0 0 1.5707963267948966" xyz="-0.069 -0.006 0.0"/>
  </joint>
  <!-- HFE output (dummy link, dummy inertia required for Gazebo) -->
  <link name="RH_HFE_output">
    <inertial>
      <origin rpy="0 0 0" xyz="0 0
   0"/>
      <mass value="0.001"/>
      <inertia ixx="0.000001" ixy="0.0" ixz="0.0" iyy="0.000001" iyz="0.0" izz="0.000001"/>
    </inertial>
  </link>  <!-- [kg * m^2] -->  <!-- [m] -->  <!-- [A] -->  <!-- Drive
   link -->
  <link name="RH_HFE_drive">
    <visual>
      <origin rpy="0
   0 0" xyz="0 0 0"/>
      <geometry>
        <mesh filename="package://anymal_d/urdf/leg/drives/drive_3_2_0_mesh.dae" scale="1.0 1.0     1.0"/>
      </geometry>
    </visual>
    <collision>
      <origin rpy="0 1.5707963267948966 0" xyz="-0.0595 0 0"/>
      <geometry>
        <cylinder length="0.119" radius="0.05375"/>
      </geometry>
    </collision>
    <inertial>
      <origin rpy="0 0 0" xyz="-0.05783 -0.00014
   0.00036"/>
      <mass value="2.01511"/>
      <inertia ixx="0.0033251482" ixy="2.567315e-05" ixz="2.599963e-05" iyy="0.00318377804" iyz="9.462185e-05" izz="0.00355095312"/>
    </inertial>
  </link>  <!-- Joint Drive output
   (or parent/output) -->
  <joint name="RH_HFE" type="revolute">
    <parent link="RH_HFE_output"/>
    <child link="RH_THIGH"/>
    <origin rpy="0
   0 0" xyz="0 0 0"/>
    <axis xyz="1 0 0"/>
    <limit command_effort="80.0" current="32.0" effort="80.0" gear_velocity="8.5" lower="-9.42477796076938" upper="9.42477796076938" velocity="8.5"/>
    <dynamics damping="0.0" friction="0.0"/>
  </joint>  <!-- Joint child link (dummy link, dummy inertia required
   for Gazebo)-->
  <link name="RH_THIGH">
    <inertial>
      <origin rpy="0 0 0" xyz="0 0 0"/>
      <mass value="0.001"/>
      <inertia ixx="0.000001" ixy="0.0" ixz="0.0" iyy="0.000001" iyz="0.0" izz="0.000001"/>
    </inertial>
  </link>
  <joint name="RH_THIGH_to_RH_HFE_drive" type="fixed">
    <parent link="RH_THIGH"/>
    <child link="RH_HFE_drive"/>
    <origin rpy="0 0
   0" xyz="0 0 0"/>
  </joint>  <!-- [kg * m^2] -->  <!-- [m] -->  <!--
   joint HFE thigh -->
  <joint name="RH_HFE_drive_RH_thigh_fixed" type="fixed">
    <parent link="RH_HFE_drive"/>
    <child link="RH_thigh_fixed"/>
    <origin rpy="0 0 -1.5707963267948966" xyz="0 0 0"/>
  </joint>  <!--
   Thigh link -->
  <link name="RH_thigh_fixed">
    <visual>
      <origin rpy="0 0 -3.141592653589793" xyz="0 0 0"/>
      <geometry>
        <mesh filename="package://anymal_d/urdf/leg/thigh/thigh_3_6_0_mesh.dae" scale="1.0
   1.0     1.0"/>
      </geometry>
    </visual>    <!-- Thigh collision -->
    <collision>
      <origin rpy="1.5707963267948966 0 0" xyz="0 -0.10519500000000001
   0"/>
      <geometry>
        <cylinder length="0.08313000000000001" radius="0.07"/>
      </geometry>
    </collision>
    <collision>
      <origin rpy="0 0 0" xyz="0 -0.09513 -0.1425"/>
      <geometry>
        <box size="0.093
   0.063 0.285"/>
      </geometry>
    </collision>
    <collision>
      <origin rpy="1.5707963267948966 0 0" xyz="0 -0.08506500000000002 -0.285"/>
      <geometry>
        <cylinder length="0.08313000000000001" radius="0.07"/>
      </geometry>
    </collision>
    <inertial>
      <origin rpy="0 0 0" xyz="0.00041 -0.09155 -0.13317"/>
      <mass value="1.10098"/>
      <inertia ixx="0.01541669135" ixy="0.00021116021" ixz="-0.00031942961" iyy="0.01630081575" iyz="-0.00143783119" izz="0.00258410631"/>
    </inertial>
  </link>
  <!-- [rad] -->  <!-- joint thigh KFE -->
  <joint name="RH_thigh_fixed_RH_KFE_drive" type="fixed">
    <parent link="RH_thigh_fixed"/>
    <child link="RH_KFE_drive" />
    <origin rpy="0 0 -1.5707963267948966" xyz="-0.0 -0.1805 -0.285"/>
  </joint>  <!-- [kg * m^2] -->  <!-- [m] -->  <!-- [A] -->  <!-- Drive
   link -->
  <link name="RH_KFE_drive">
    <visual>
      <origin rpy="0
   0 0" xyz="0 0 0"/>
      <geometry>
        <mesh filename="package://anymal_d/urdf/leg/drives/drive_3_2_0_mesh.dae" scale="1.0 1.0     1.0"/>
      </geometry>
    </visual>
    <collision>
      <origin rpy="0 1.5707963267948966 0" xyz="-0.0595 0 0"/>
      <geometry>
        <cylinder length="0.119" radius="0.05375"/>
      </geometry>
    </collision>
    <inertial>
      <origin rpy="0 0 0" xyz="-0.05783 -0.00014
   0.00036"/>
      <mass value="2.01511"/>
      <inertia ixx="0.0033251482" ixy="2.567315e-05" ixz="2.599963e-05" iyy="0.00318377804" iyz="9.462185e-05" izz="0.00355095312"/>
    </inertial>
  </link>  <!-- Joint Drive output
   (or parent/output) -->
  <joint name="RH_KFE" type="revolute">
    <parent link="RH_KFE_drive"/>
    <child link="RH_SHANK"/>
    <origin rpy="0 0
   0" xyz="0 0 0"/>
    <axis xyz="-1 0 0"/>
    <limit command_effort="80.0" current="32.0" effort="80.0" gear_velocity="8.5" lower="-9.42477796076938" upper="9.42477796076938" velocity="8.5"/>
    <dynamics damping="0.0" friction="0.0"/>
  </joint>  <!-- Joint child link (dummy link, dummy inertia required
   for Gazebo)-->
  <link name="RH_SHANK">
    <inertial>
      <origin rpy="0 0 0" xyz="0 0 0"/>
      <mass value="0.001"/>
      <inertia ixx="0.000001" ixy="0.0" ixz="0.0" iyy="0.000001" iyz="0.0" izz="0.000001"/>
    </inertial>
  </link>  <!-- [m] -->  <!-- joint KFE shank -->
  <joint name="RH_shank_RH_shank_fixed" type="fixed">
    <parent link="RH_SHANK"/>
    <child link="RH_shank_fixed" />
    <origin rpy="0 0 1.5707963267948966" xyz="0 0 0"/>
  </joint>  <!--
   Shank link -->
  <link name="RH_shank_fixed">
    <visual>
      <origin rpy="0 0 -3.141592653589793" xyz="0 0 0"/>
      <geometry>
        <mesh filename="package://anymal_d/urdf/leg/shank/shank_3_6_0_mesh.dae" scale="1.0
   1.0     1.0"/>
      </geometry>
    </visual>    <!-- Shank collision -->
    <collision>
      <origin rpy="1.5707963267948966 0 0" xyz="0 0 0"/>
      <geometry>
        <cylinder length="0.05732" radius="0.071"/>
      </geometry>
    </collision>
    <collision>
      <origin rpy="1.5707963267948966
   0 0" xyz="-0.066415 0 0"/>
      <geometry>
        <box size="0.13283 0.08302
   0.05732"/>
      </geometry>
    </collision>
    <inertial>
      <origin rpy="0 0 0" xyz="-0.02186 -0.00895 0.00042"/>
      <mass value="0.49854" />
      <inertia ixx="0.00054939614" ixy="2.147115e-05" ixz="-1.687902e-05" iyy="0.00166971314" iyz="-1.71584e-06" izz="0.00127258622"/>
    </inertial>
  </link>  <!-- [kg * m^2] -->  <!-- Leg configurations: xx (knees bent inwards),
   xo (knees bent backwards) -->  <!-- joint shank foot -->
  <joint name="RH_shank_fixed_RH_FOOT" type="fixed">
    <parent link="RH_shank_fixed"/>
    <child link="RH_FOOT" />
    <origin rpy="0 0 0" xyz="-0.1 -0.02225 -0.39246"/>
  </joint>  <!--
   Foot link -->
  <link name="RH_FOOT">
    <visual>
      <origin rpy="0
   0 -3.141592653589793" xyz="0 0 0"/>
      <geometry>
        <mesh filename="package://anymal_d/urdf/leg/foot/foot_3_6_1_mesh.dae" scale="1.0 1.0     1.0" />
      </geometry>
    </visual>    <!-- Foot tube collision -->
    <collision>
      <origin rpy="0 0 0" xyz="0 0.016891153063699788 0.22824319686592265" />
      <geometry>
        <cylinder length="0.39572" radius="0.0175"/>
      </geometry>
    </collision>    <!-- Foot ball collision -->
    <collision>
      <origin xyz="0 0.008141153063699788 0.03038319686592264"/>
      <geometry>
        <sphere radius="0.031455"/>
      </geometry>
    </collision>
    <inertial>
      <origin rpy="0 0 0" xyz="-0.0 0.01559 0.15004"/>
      <mass value="0.29644"/>
      <inertia ixx="0.00514263169" ixy="1.46e-09" ixz="-6.85e-09" iyy="0.0051315957" iyz="-0.00016323086" izz="0.00011890148" />
    </inertial>
  </link>  <!-- Gazebo customization -->
  <gazebo reference="RH_FOOT">
    <kp>1000000.0</kp>
    <kd>100.0</kd>
    <mu1>0.8</mu1>
    <mu2>0.8</mu2>
  </gazebo>  <!-- [kg * m^2] -->  <!-- Fixed joint base hatch
   -->
  <joint name="base_hatch_shell" type="fixed">
    <parent link="base" />
    <child link="hatch_shell"/>
    <origin rpy="0 0 0" xyz="0 0 0"/>
  </joint>  <!-- Hatch link -->
  <link name="hatch_shell">
    <visual>
      <origin rpy="0 0 0" xyz="0.0 0 0.0"/>
      <geometry>
        <mesh filename="package://anymal_d/urdf/base/shell/hatch_shell_3_6_0_mesh.dae" scale="1.0 1.0 1.0"/>
      </geometry>
    </visual>
    <inertial>
      <origin rpy="0 0 0" xyz="0.06631 0.00035 0.10319"/>
      <mass value="0.09653" />
      <inertia ixx="0.00019173168" ixy="2.292922e-05" ixz="3.08205e-06" iyy="0.0014487952" iyz="5.84565e-06" izz="0.00162332503"/>
    </inertial>
  </link>
  <joint name="joint_base" type="fixed">
    <parent link="base" />
    <child link="dynaarm_base"/>
    <origin rpy="0 0 0" xyz="0.16525
   0.0 0.204"/>
    <limit effort="2000" lower="0" upper="0" velocity="0"/>
    <!-- limit effort also defines torque limit and freeze controller gains
   -->
    <dynamics damping="0.0" friction="0.0"/>
  </joint>
  <link name="dynaarm_base">
    <visual>
      <geometry>
        <mesh filename="package://dynaarm_urdf/meshes/0_base_mesh.dae" />
      </geometry>
    </visual>
    <collision>
      <origin rpy="0 0 0" xyz="0 0 -0.04"/>
      <geometry>        <!--<mesh filename="package://dynaarm_urdf/meshes/300_base_anymal_mesh_col.dae" />-->
        <cylinder length="0.08" radius="0.06"/>
      </geometry>
    </collision>
  </link>  <!-- Fixed joint to add dummy inertia link -->
  <joint name="dynaarm_base_to_dynaarm_base_inertia" type="fixed">
    <parent link="dynaarm_base"/>
    <child link="dynaarm_base_inertia"/>
    <origin rpy="0 0 0" xyz="0 0 0"/>
  </joint>  <!-- Dummy inertia link, because
   KDL cannot have inertia on the base link -->
  <link name="dynaarm_base_inertia">
    <inertial>
      <mass value="1.53"/>
      <origin rpy="0 0 0" xyz="2.6302342999999998e-05 -0.000226836219 -0.03053573033"/>
      <inertia ixx="0.0018534" ixy="-4.535e-06" ixz="9.01e-07" iyy="0.0018514" iyz="5.559454625e-06" izz="0.0022344699999999997"/>
    </inertial>
  </link>
  <link name="dynaarm_SHOULDER">
    <visual>
      <geometry>
        <mesh filename="package://dynaarm_urdf/meshes/100_shoulder_mesh.dae" scale="1.0 1.0 1.0"/>
      </geometry>
    </visual>
    <collision>
      <origin rpy="1.57 0 0" xyz="0 0 0"/>
      <geometry>
        <cylinder length="0.24" radius="0.05"/>
      </geometry>
    </collision>
    <inertial>
      <mass value="2.644"/>
      <origin rpy="0 0 0" xyz="0.0 0.0 -0.0017336" />
      <inertia ixx="0.010301209999999998" ixy="-5.0849999999999996e-05" ixz="0.0" iyy="0.0030164999999999997" iyz="0.0" izz="0.01009904"/>
    </inertial>
  </link>
  <link name="dynaarm_UPPERARM">
    <visual>
      <geometry>
        <mesh filename="package://dynaarm_urdf/meshes/200_upperarm_mesh.dae" scale="1.0 1.0 1.0"/>
      </geometry>
    </visual>
    <collision>
      <origin rpy="1.57 0 1.57" xyz="0.25 0 0"/>
      <geometry>
        <cylinder length="0.4" radius="0.05"/>
      </geometry>
    </collision>
    <inertial>
      <mass value="1.394"/>
      <origin rpy="0 0 0" xyz="0.21109 2.2e-05 -0.000317"/>
      <inertia ixx="0.00116179" ixy="-7.2e-07" ixz="-0.00014044999999999997" iyy="0.046092126" iyz="7e-09" izz="0.04627953" />
    </inertial>
  </link>
  <link name="dynaarm_ELBOW">
    <visual>
      <geometry>
        <mesh filename="package://dynaarm_urdf/meshes/300_elbow_mesh.dae" scale="1.0 1.0 1.0"/>
      </geometry>
    </visual>
    <collision>
      <origin rpy="0 1.57 0" xyz="0.185 -0.0935 0"/>
      <geometry>
        <cylinder length="0.46" radius="0.047"/>
      </geometry>
    </collision>
    <inertial>
      <mass value="1.1"/>
      <origin rpy="0 0 0" xyz="0.0068 -0.0848 -0.0006"/>
      <inertia ixx="0.0013843" ixy="-4.16e-05" ixz="8.5e-06" iyy="0.0007168" iyz="-1.05e-05" izz="0.0011300999999999998"/>
    </inertial>
  </link>
  <joint name="SH_ROT" type="revolute">
    <parent link="dynaarm_base"/>
    <child link="dynaarm_SHOULDER"/>
    <axis xyz="0 0 1"/>
    <limit command_effort="40" current="10" effort="40" gear_velocity="4" lower="-2.999992653589793" upper="2.999992653589793" velocity="4"/>
    <!-- limit effort also defines torque limit and freeze controller gains -->
    <origin rpy="0 0 0" xyz="0 0 0.06"/>
    <dynamics damping="0.3" friction="0.0"/>
  </joint>
  <joint name="SH_FLE" type="revolute">
    <parent link="dynaarm_SHOULDER"/>
    <child link="dynaarm_UPPERARM"/>
    <axis xyz="0
   0 -1"/>
    <limit command_effort="40" current="10" effort="40" gear_velocity="4" lower="-1.9707963267948965" upper="1.9707963267948965" velocity="4"/>
    <!-- limit effort also defines torque limit and freeze controller gains -->
    <origin rpy="1.5707963267948966 -1.5707963267948966 0" xyz="0 0 0.0"/>
    <dynamics damping="0.3" friction="0.0"/>
  </joint>
  <joint name="EL_FLE" type="revolute">
    <parent link="dynaarm_UPPERARM"/>
    <child link="dynaarm_ELBOW"/>
    <axis xyz="0 0 1"/>
    <limit command_effort="40" current="10" effort="40" gear_velocity="4" lower="-0.2" upper="3.141592653589793" velocity="4"/>
    <!-- limit effort also defines torque limit and freeze controller
   gains -->
    <origin rpy="3.141592653589793 0 0" xyz="0.412 0 0"/>
    <dynamics damping="0.3" friction="0.0"/>
  </joint>
  <link name="dynaarm_FOREARM">
    <visual>
      <geometry>
        <mesh filename="package://dynaarm_urdf/meshes/400_forearm_4tube_longer_mesh.dae" scale="1.0 1.0 1.0"/>
      </geometry>
    </visual>
    <inertial>
      <mass value="0.154"/>
      <origin rpy="0 0 0" xyz="0.0 0.0 0.133" />
      <inertia ixx="0.0018499999999999999" ixy="0.0" ixz="0.0" iyy="0.001849" iyz="0.0" izz="0.00011499999999999999"/>
    </inertial>
  </link>
  <!--Add Realsense-->
  <joint name="FA_ROT" type="revolute">
    <parent link="dynaarm_ELBOW"/>
    <child link="dynaarm_FOREARM"/>
    <axis xyz="0 0 1"/>
    <limit command_effort="40" current="10" effort="40" gear_velocity="4" lower="-3.999992653589793" upper="3.999992653589793" velocity="4"/>
    <!-- limit effort also defines torque limit and freeze controller gains -->
    <origin rpy="1.5707963267948966 0 1.5707963267948966" xyz="0.0325 -0.092
   0"/>
    <dynamics damping="0.3" friction="0.0"/>
  </joint>
  <link name="dynaarm_FOREARM_wrist1">
    <visual>
      <geometry>
        <mesh filename="package://dynaarm_urdf/meshes/406_forearm_4tube_wrist1_mesh.dae" scale="1.0 1.0
   1.0"/>
      </geometry>
    </visual>
    <inertial>
      <mass value="0.05"/>
      <origin rpy="0 0 0" xyz="0.0 -0.0284 0.0223"/>
      <inertia ixx="3.2e-05" ixy="0.0" ixz="0.0" iyy="3.2999999999999996e-05" iyz="-5.4e-06" izz="1.7e-05"/>
    </inertial>
  </link>
  <joint name="FA_ROT_wrist1" type="fixed">
    <parent link="dynaarm_FOREARM"/>
    <child link="dynaarm_FOREARM_wrist1" />
    <origin rpy="0 0 0" xyz="0.0 0.0 0.37"/>
    <limit effort="2000" lower="0" upper="0" velocity="0"/>
    <!-- limit effort also defines torque
   limit and freeze controller gains -->
    <dynamics damping="0.0" friction="0.0"/>
  </joint>
  <link name="dynaarm_WRIST_1">
    <visual>
      <geometry>
        <mesh filename="package://dynaarm_urdf/meshes/500_wrist1_mesh.dae" scale="1.0 1.0 1.0"/>
      </geometry>
    </visual>
    <collision>
      <origin rpy="0 1.5707963267948966 0" xyz="0.045 0 0.03"/>
      <geometry>
        <cylinder length="0.18" radius="0.055"/>
      </geometry>
    </collision>
    <inertial>
      <mass value="1.79"/>
      <origin rpy="0 0 0" xyz="0.047 0.0 0.029"/>
      <inertia ixx="0.0016719999999999999" ixy="0.0" ixz="0.00012969999999999998" iyy="0.004985" iyz="-3.7e-06" izz="0.005209999999999999" />
    </inertial>
  </link>
  <link name="dynaarm_WRIST_2">
    <visual>
      <geometry>
        <mesh filename="package://dynaarm_urdf/meshes/600_wrist2_plate_mesh.dae" scale="1.0 1.0 1.0"/>
      </geometry>
    </visual>
    <inertial>
      <mass value="0.03"/>
      <origin rpy="0 0 0" xyz="0.0 0.0 0.0064" />
      <inertia ixx="7.4e-06" ixy="0.0" ixz="0.0" iyy="7.4e-06" iyz="0.0" izz="1.4199999999999998e-05"/>
    </inertial>
  </link>
  <joint name="WRIST_1" type="revolute">
    <parent link="dynaarm_FOREARM_wrist1"/>
    <child link="dynaarm_WRIST_1"/>
    <axis xyz="0 0 1"/>
    <limit command_effort="40" current="10" effort="40" gear_velocity="4" lower="-1.5707963267948966" upper="1.5707963267948966" velocity="4"/>
    <!-- limit effort also defines
   torque limit and freeze controller gains -->
    <origin rpy="0 -1.5707963267948966
   -1.5707963267948966" xyz="0.0 -0.03 0.055"/>
    <dynamics damping="0.3" friction="0.0"/>
  </joint>
  <joint name="WRIST_2" type="revolute">
    <parent link="dynaarm_WRIST_1"/>
    <child link="dynaarm_WRIST_2"/>
    <axis xyz="0 0 1"/>
    <limit command_effort="40" current="10" effort="40" gear_velocity="4" lower="-3.141592653589793" upper="3.141592653589793" velocity="4"/>
    <!-- limit effort also defines torque limit and freeze controller
   gains -->
    <origin rpy="0 1.5707963267948966 0" xyz="0.12 0.0 0.03"/>
    <dynamics damping="0.3" friction="0.0"/>
  </joint>
  <link name="ftSensor_interfacePlate">
    <visual>
      <geometry>
        <mesh filename="package://dynaarm_urdf/meshes/404_forearm_4tube_ftsPlate_mesh.dae" scale="1.0 1.0 1.0"/>
      </geometry>
    </visual>
    <inertial>
      <mass value="0.03"/>
      <origin rpy="0 0 0" xyz="0.0 0.0 0.003"/>
      <inertia ixx="9.999999999999999e-06" ixy="0.0" ixz="0.0" iyy="9.999999999999999e-06" iyz="0.0" izz="1.9999999999999998e-05"/>
    </inertial>
  </link>
  <joint name="ftSensor_interfacePlate" type="fixed">
    <parent link="dynaarm_WRIST_2" />
    <child link="ftSensor_interfacePlate"/>
    <origin rpy="0 0 0" xyz="0 0 0"/>
    <limit effort="2000" lower="0" upper="0" velocity="0"/>
    <!-- limit effort also defines torque limit and freeze controller gains -->
    <dynamics damping="0.0" friction="0.0"/>
  </joint>
  <link name="ftSensor_interfacePlate2">
    <visual>
      <geometry>
        <mesh filename="package://dynaarm_urdf/meshes/404_forearm_4tube_ftsPlate_mesh.dae" scale="1.0 1.0 1.0"/>
      </geometry>
    </visual>
    <inertial>
      <mass value="0.03"/>
      <origin rpy="0 0 0" xyz="0.0 0.0 0.003"/>
      <inertia ixx="9.999999999999999e-06" ixy="0.0" ixz="0.0" iyy="9.999999999999999e-06" iyz="0.0" izz="1.9999999999999998e-05"/>
    </inertial>
  </link>
  <joint name="ftSensor_interfacePlate2" type="fixed">
    <parent link="ftSensor_interfacePlate" />
    <child link="ftSensor_interfacePlate2"/>
    <origin rpy="0 0 0" xyz="0 0 0.006"/>
    <limit effort="2000" lower="0" upper="0" velocity="0" />
    <!-- limit effort also defines torque limit and freeze controller gains
   -->
    <dynamics damping="0.0" friction="0.0"/>
  </joint>
  <link name="realsense_base">    <!-- used in the elbow joint to attach to the mimic joint
   and and to the elbow joint -->
    <visual>
      <origin rpy="0 0 0" xyz="-0.0005 0 0"/>
      <geometry>
        <box size="0.001 0.001 0.001"/>
      </geometry>
    </visual>
    <inertial>
      <origin rpy="0 0 0" xyz="0.0 0.0 0.0"/>
      <mass value="1e-6"/>
      <inertia ixx="1e-6" ixy="0.0" ixz="0.0" iyy="1e-6" iyz="0.0" izz="1e-6"/>
    </inertial>
  </link>
  <gazebo reference="realsense_base">
    <kp>10000.0</kp>
    <kd>10.0</kd>
    <mu1>0.8</mu1>
    <mu2>0.8</mu2>
  </gazebo>
  <joint name="gripper_base_joint" type="fixed">
    <parent link="ftSensor_interfacePlate2"/>
    <child link="realsense_base"/>
    <origin rpy="0 0 -1.5707963267948966" xyz="0 0 0.006" />
    <limit effort="2000" lower="0" upper="0" velocity="0"/>
    <!--
   limit effort also defines torque limit and freeze controller gains -->
    <dynamics damping="0.0" friction="0.0"/>
  </joint>
  <link name="gripper_base">    <!-- used in the elbow joint to attach to the mimic joint and and to the
   elbow joint -->
    <visual>
      <origin rpy="0 0 0" xyz="-0.0005 0 0" />
      <geometry>
        <box size="0.001 0.001 0.001"/>
      </geometry>
    </visual>
    <inertial>
      <origin rpy="0 0 0" xyz="0.0 0.0 0.0" />
      <mass value="1e-6"/>
      <inertia ixx="1e-6" ixy="0.0" ixz="0.0" iyy="1e-6" iyz="0.0" izz="1e-6"/>
    </inertial>
  </link>
  <gazebo reference="gripper_base">
    <kp>10000.0</kp>
    <kd>10.0</kd>
    <mu1>0.8</mu1>
    <mu2>0.8</mu2>
  </gazebo>
  <joint name="WRIST_2_realsense_base" type="fixed">
    <parent link="realsense_base"/>
    <child link="gripper_base" />
    <origin rpy="0 0 0" xyz="0.0 0.0 0.0"/>
    <limit effort="2000" lower="0" upper="0" velocity="0"/>
    <!-- limit effort also defines torque
   limit and freeze controller gains -->
    <dynamics damping="0.0" friction="0.0"/>
  </joint>
  <link name="dynaarm_END_EFFECTOR">    <!-- used in the
   elbow joint to attach to the mimic joint and and to the elbow joint -->
    <visual>
      <origin rpy="0 0 0" xyz="-0.0005 0 0"/>
      <geometry>
        <box size="0.001 0.001 0.001"/>
      </geometry>
    </visual>
    <inertial>
      <origin rpy="0 0 0" xyz="0.0 0.0 0.0"/>
      <mass value="1e-6"/>
      <inertia ixx="1e-6" ixy="0.0" ixz="0.0" iyy="1e-6" iyz="0.0" izz="1e-6"/>
    </inertial>
  </link>
  <gazebo reference="dynaarm_END_EFFECTOR">
    <kp>10000.0</kp>
    <kd>10.0</kd>
    <mu1>0.8</mu1>
    <mu2>0.8</mu2>
  </gazebo>
  <joint name="ee_fix_joint" type="fixed">
    <parent link="gripper_base"/>
    <child link="dynaarm_END_EFFECTOR"/>
    <origin rpy="0 0 0" xyz="0 0 0"/>
    <limit effort="2000" lower="0" upper="0" velocity="0"/>
    <!-- limit effort also defines torque limit and freeze controller gains
   -->
    <dynamics damping="0.0" friction="0.0"/>
  </joint>
  <gazebo reference="dynaarm_END_EFFECTOR">
    <kp>10000.0</kp>
    <kd>10.0</kd>
    <mu1>0.8</mu1>
    <mu2>0.8</mu2>
  </gazebo>
  <link name="dynaarm_interface">
    <visual>
      <geometry>
        <mesh filename="package://dynaarm_urdf/meshes/1000_dynaarm_interface_parts.dae" scale="1.0 1.0 1.0"/>
      </geometry>
    </visual>
  </link>
  <joint name="dynaarm_interface_parts_joint" type="fixed">
    <parent link="base" />
    <child link="dynaarm_interface"/>
    <origin rpy="1.5707963267948966
   0 1.5707963267948966" xyz="0 0 0.059"/>
    <limit effort="2000" lower="0" upper="0" velocity="0"/>
    <!-- limit effort also defines torque limit
   and freeze controller gains -->
    <dynamics damping="0.0" friction="0.0" />
  </joint>
  <link name="collision_base">
    <collision>
      <origin rpy="0 0 0" xyz="0 0 0"/>
      <geometry>
        <box size="0.9 0.34
   0.2"/>
      </geometry>
    </collision>
  </link>
  <joint name="collision_base_joint" type="fixed">
    <parent link="base"/>
    <child link="collision_base" />
    <origin rpy="0 0 0" xyz="0 0 0"/>
  </joint>
  <link name="collision_lidar">
    <collision>
      <origin rpy="0 0 0" xyz="0 0 0.02"/>
      <geometry>
        <cylinder length="0.14" radius="0.09"/>
      </geometry>
    </collision>
  </link>
  <joint name="collision_lidar_joint" type="fixed">
    <parent link="lidar"/>
    <child link="collision_lidar"/>
    <origin rpy="0 0
   0" xyz="0 0 0"/>
  </joint>
</robot>